Traceback (most recent call last):
  File "c:\users\sophi\anaconda3\lib\site-packages\jupyter_cache\executors\utils.py", line 56, in single_nb_execution
    record_timing=False,
  File "c:\users\sophi\anaconda3\lib\site-packages\nbclient\client.py", line 1112, in execute
    return NotebookClient(nb=nb, resources=resources, km=km, **kwargs).execute()
  File "c:\users\sophi\anaconda3\lib\site-packages\nbclient\util.py", line 74, in wrapped
    return just_run(coro(*args, **kwargs))
  File "c:\users\sophi\anaconda3\lib\site-packages\nbclient\util.py", line 53, in just_run
    return loop.run_until_complete(coro)
  File "c:\users\sophi\anaconda3\lib\asyncio\base_events.py", line 587, in run_until_complete
    return future.result()
  File "c:\users\sophi\anaconda3\lib\site-packages\nbclient\client.py", line 554, in async_execute
    cell, index, execution_count=self.code_cells_executed + 1
  File "c:\users\sophi\anaconda3\lib\site-packages\nbclient\client.py", line 857, in async_execute_cell
    self._check_raise_for_error(cell, exec_reply)
  File "c:\users\sophi\anaconda3\lib\site-packages\nbclient\client.py", line 760, in _check_raise_for_error
    raise CellExecutionError.from_cell_and_msg(cell, exec_reply_content)
nbclient.exceptions.CellExecutionError: An error occurred while executing the following cell:
------------------
df = read_data()
df = transform_data(df)
train_dataset, evaluate_dataset, train_dataset_total, test_dataset = split_data(df)
train_dataset = fill_missingdata(train_dataset)
train_dataset = add_feautures(train_dataset)
train_dataset
------------------

[1;31m---------------------------------------------------------------------------[0m
[1;31mValueError[0m                                Traceback (most recent call last)
[1;32m~\AppData\Local\Temp/ipykernel_960/2720515760.py[0m in [0;36m<module>[1;34m[0m
[0;32m      1[0m [0mdf[0m [1;33m=[0m [0mread_data[0m[1;33m([0m[1;33m)[0m[1;33m[0m[1;33m[0m[0m
[0;32m      2[0m [0mdf[0m [1;33m=[0m [0mtransform_data[0m[1;33m([0m[0mdf[0m[1;33m)[0m[1;33m[0m[1;33m[0m[0m
[1;32m----> 3[1;33m [0mtrain_dataset[0m[1;33m,[0m [0mevaluate_dataset[0m[1;33m,[0m [0mtrain_dataset_total[0m[1;33m,[0m [0mtest_dataset[0m [1;33m=[0m [0msplit_data[0m[1;33m([0m[0mdf[0m[1;33m)[0m[1;33m[0m[1;33m[0m[0m
[0m[0;32m      4[0m [0mtrain_dataset[0m [1;33m=[0m [0mfill_missingdata[0m[1;33m([0m[0mtrain_dataset[0m[1;33m)[0m[1;33m[0m[1;33m[0m[0m
[0;32m      5[0m [0mtrain_dataset[0m [1;33m=[0m [0madd_feautures[0m[1;33m([0m[0mtrain_dataset[0m[1;33m)[0m[1;33m[0m[1;33m[0m[0m

[1;31mValueError[0m: not enough values to unpack (expected 4, got 2)
ValueError: not enough values to unpack (expected 4, got 2)

